Workbook

Sheet Sommaire
A1: CAHIER DE TESTS — CESIZen
A3: Référentiel formel des cas de test couvrant l'ensemble de l'application (web Next.js, API REST, mobile Expo).
A5: Version | B5: 1.0
A6: Date | B6: 2026-05-04
A7: Périmètre | B7: Application CESIZen — toutes surfaces
A8: Références | B8: FLUX_DONNEES.md, TESTS_ET_CI.md, README.md
A9: Norme | B9: Inspiré ISO/IEC/IEEE 29119 (simplifié)
A12: SOMMAIRE
A13: Onglet | B13: Description
A14: 1. Stratégie | B14: 1. Stratégie de test
A15: 2. Environnements | B15: Environnements et versions cibles
A16: 3. Données de test | B16: Comptes pré-provisionnés, émotions et articles seed
A17: 4. Critères E-S | B17: Critères d'entrée et de sortie
A18: 5. Matrice | B18: Matrice de couverture exigences ↔ tests
A19: 6. AUTH | B19: Cas de test — Authentification (15)
A20: 7. JRN | B20: Cas de test — Journal émotionnel (20)
A21: 8. STAT | B21: Cas de test — Statistiques (8)
A22: 9. CONS | B22: Cas de test — Conseils / Articles (10)
A23: 10. ADM | B23: Cas de test — Administration (18)
A24: 11. MOB | B24: Cas de test — Mobile spécifique (15)
... A28: Annexe B | B28: Classification des anomalies

Sheet 1. Stratégie
A1: 1. Stratégie de test
A3: 1.1 Niveaux de test
A4: Niveau | B4: Outil | C4: Pour quoi
A5: Unitaire | B5: Vitest (web), Jest (mobile) | C5: Logique pure : hash, chiffrement, validation, helpers
A6: Intégration | B6: Vitest + Supertest (Route Handlers Next directs) | C6: Endpoints API + DB + chiffrement bout-en-bout
A7: E2E | B7: Playwright (web), Maestro (mobile) | C7: Parcours utilisateur complets multi-pages
A8: Manuel exploratoire | B8: Humain | C8: UX, lisibilité, cohérence visuelle
A10: 1.2 Types de test
A11: Type | B11: Description
A12: Fonctionnel | B12: Comportement métier conforme à la spécification
A13: Sécurité | B13: RBAC, ownership, chiffrement, JWT, headers
A14: Robustesse | B14: Gestion des entrées invalides, cas limites, erreurs réseau
A15: Régression | B15: Sous-ensemble joué à chaque release
A16: Compatibilité | B16: Chrome / Firefox / Safari (web) ; iOS / Android (mobile)
A18: 1.3 Criticité (priorité d'exécution)
A19: Niveau | B19: Définition | C19: Exemple
A20: Bloquant | B20: Échec = pas de mise en prod | C20: Login impossible, perte de données utilisateur
A21: Haute | B21: À corriger avant release | C21: Stats erronées, ban contournable
A22: Moyenne | B22: À corriger dans la version + 1 | C22: Filtre articles bug, message d'erreur peu clair
A23: Basse | B23: Backlog | C23: Animation saccadée, libellé typo

Sheet 2. Environnements
A1: 2. Environnements
A3: 2.1 Environnements applicatifs
A4: Environnement | B4: URL Web | C4: API Mobile | D4: Base de données | E4: Usage
A5: Local dev | B5: http://localhost:3000 | C5: http://localhost:3000 | D5: Postgres local | E5: Développement
A6: CI | B6: localhost:3000 (éphémère) | C6: — | D6: Postgres service container | E6: Pipeline automatisé
A7: Staging / Recette | B7: https://recette.cesizen.fr | C7: https://recette.cesizen.fr | D7: Base dédiée recette | E7: UAT
A8: Production | B8: https://cesizen.fr | C8: https://cesizen.fr | D8: Base prod | E8: Live
A10: 2.2 Versions cibles
A11: Plateforme | B11: Versions supportées
A12: Navigateurs web | B12: Chrome 120+, Firefox 120+, Safari 17+, Edge 120+
A13: iOS | B13: 16.0+
A14: Android | B14: API 24+ (Android 7.0+)
A15: Résolutions | B15: 360×640 (mobile) → 1920×1080 (desktop)

Sheet 3. Données de test
A1: 3. Données de test
A3: 3.1 Comptes pré-provisionnés (recette)
A4: Login | B4: Mot de passe | C4: Rôle | D4: État
A5: admin@cesizen.fr | B5: Admin1234! | C5: admin | D5: actif
A6: demo@cesizen.fr | B6: Demo1234 | C6: user | D6: actif
A7: banned@cesizen.fr | B7: Banned1234 | C7: user | D7: banni
A8: empty@cesizen.fr | B8: Empty1234 | C8: user | D8: actif (0 entrée)
A10: 3.2 Référentiel d'émotions seed
A11: Catégorie | B11: Couleur | C11: Émotions
A12: Joie | B12: #FFD700 | C12: Heureux, Fier, Apaisé, Reconnaissant
A13: Tristesse | B13: #4682B4 | C13: Mélancolique, Découragé, Solitaire
A14: Colère | B14: #DC143C | C14: Frustré, Irrité, Furieux
A15: Peur | B15: #800080 | C15: Anxieux, Inquiet, Stressé
A16: Surprise | B16: #FFA500 | C16: Étonné, Émerveillé
A18: 3.3 Articles seed
A19: Au moins 5 articles publiés dont 1 par catégorie (Bien-être, Stress, Sommeil, Travail, Émotions).

Sheet 4. Critères E-S
A1: 4. Critères d'entrée et de sortie
A3: 4.1 Critères d'entrée d'une campagne de test
A4: # | B4: Critère
A5: 1 | B5: Build déployé sur l'environnement cible
A6: 2 | B6: Migrations DB appliquées (drizzle-kit migrate)
A7: 3 | B7: Données seed chargées
A8: 4 | B8: Comptes de test créés
A9: 5 | B9: Documentation à jour
A10: 6 | B10: Pipeline CI vert sur la branche
A12: 4.2 Critères de sortie
A13: # | B13: Critère
A14: 1 | B14: 100 % des cas Bloquants OK
A15: 2 | B15: ≥ 95 % des cas Hautes OK
A16: 3 | B16: ≥ 85 % des cas Moyennes OK
A17: 4 | B17: Aucune anomalie Bloquante ouverte
A18: 5 | B18: Tous les correctifs livrés ont leur test de non-régression
A19: 6 | B19: PV de recette signé

Sheet 5. Matrice
A1: 5. Matrice de couverture
A3: Exigence métier | B3: Cas de test associés
A4: Un citoyen peut créer un compte | B4: CT-AUTH-001, CT-AUTH-002, CT-AUTH-003
A5: Un citoyen peut se connecter | B5: CT-AUTH-004, CT-AUTH-005, CT-AUTH-006, CT-AUTH-007
A6: Les notes sont chiffrées au repos | B6: CT-JRN-005, CT-SEC-001, CT-ADM-013
A7: Un user ne lit pas les entrées d'un autre | B7: CT-JRN-009, CT-JRN-010, CT-SEC-006
A8: Les admins ne voient pas les notes en clair | B8: CT-SEC-001, CT-ADM-013
A9: L'app mobile persiste la session | B9: CT-MOB-001, CT-MOB-002
A10: Un admin peut bannir un user | B10: CT-ADM-005, CT-ADM-006
A11: Un admin ne peut pas se ban lui-même | B11: CT-ADM-007
A12: Les statistiques reflètent les entrées du user | B12: CT-STAT-001 à CT-STAT-008
A13: Les articles brouillons restent invisibles | B13: CT-CONS-007, CT-CONS-008
A14: Mot de passe robuste (8+, maj, min, chiffre) | B14: CT-AUTH-013, CT-AUTH-014
A15: Les sessions JWT expirent à 7 jours | B15: CT-AUTH-009, CT-SEC-008

Sheet All
A1: Vue consolidée — 98 cas de test
A2: Synchronisé avec les onglets modules : Statut, Date, Testeur, Commentaire et ID anomalie sont remontés via VLOOKUP. Toute modification sur un onglet module se reflète ici automatiquement.
A3: Module | B3: ID | C3: Titre | D3: Niveau | E3: Criticité | F3: Préconditions | G3: Données | H3: Étapes | I3: Résultat attendu | J3: Automatisé | K3: Statut | L3: Date exécution | M3: Testeur | N3: Commentaire | O3: ID anomalie
A4: AUTH | B4: CT-AUTH-001 | C4: Inscription nominale | D4: Intégration | E4: Bloquant | F4: Aucun compte avec l'email cible n'existe en DB | G4: email=new@test.com, password=Password1, confirm=Password1, prenom=Jane, nom=Doe | H4: 1. POST /api/auth/register avec le body 2. Lire la réponse | I4: • HTTP 200 • body.success === true • body.token au format JWT (3 segments séparés par .) • Cookie session posé httpOnly + sameSite=lax • Ligne créée dans users avec role='user' et isBanned=false | J4: ✅ tests/integration/auth.test.ts | K4: =IFERROR(VLOOKUP(B4,'6. AUTH'!A:N,10,FALSE()),"") | L4: =IFERROR(VLOOKUP(B4,'6. AUTH'!A:N,11,FALSE()),"") | M4: =IFERROR(VLOOKUP(B4,'6. AUTH'!A:N,12,FALSE()),"") | N4: =IFERROR(VLOOKUP(B4,'6. AUTH'!A:N,13,FALSE()),"") | O4: =IFERROR(VLOOKUP(B4,'6. AUTH'!A:N,14,FALSE()),"")
A5: AUTH | B5: CT-AUTH-002 | C5: Inscription rejetée pour mot de passe faible | D5: Intégration | E5: Haute | F5: — | G5: email=a@b.co, password=short, confirm=short | H5: POST /api/auth/register | I5: HTTP 400 + body.fieldErrors.password non vide (regex maj/min/chiffre/8 car) | J5: ✅ | K5: =IFERROR(VLOOKUP(B5,'6. AUTH'!A:N,10,FALSE()),"") | L5: =IFERROR(VLOOKUP(B5,'6. AUTH'!A:N,11,FALSE()),"") | M5: =IFERROR(VLOOKUP(B5,'6. AUTH'!A:N,12,FALSE()),"") | N5: =IFERROR(VLOOKUP(B5,'6. AUTH'!A:N,13,FALSE()),"") | O5: =IFERROR(VLOOKUP(B5,'6. AUTH'!A:N,14,FALSE()),"")
A6: AUTH | B6: CT-AUTH-003 | C6: Inscription rejetée pour email déjà utilisé | D6: Intégration | E6: Haute | F6: Un user dup@test.com existe | G6: email=dup@test.com | H6: POST /api/auth/register avec ce même email | I6: HTTP 409 + body.error contient « existe déjà » | J6: ✅ | K6: =IFERROR(VLOOKUP(B6,'6. AUTH'!A:N,10,FALSE()),"") | L6: =IFERROR(VLOOKUP(B6,'6. AUTH'!A:N,11,FALSE()),"") | M6: =IFERROR(VLOOKUP(B6,'6. AUTH'!A:N,12,FALSE()),"") | N6: =IFERROR(VLOOKUP(B6,'6. AUTH'!A:N,13,FALSE()),"") | O6: =IFERROR(VLOOKUP(B6,'6. AUTH'!A:N,14,FALSE()),"")
A7: AUTH | B7: CT-AUTH-004 | C7: Connexion nominale | D7: Intégration | E7: Bloquant | F7: Compte log@test.com / Password123 actif | G7: — | H7: POST /api/auth/login | I7: HTTP 200 + token JWT + cookie session posé | J7: ✅ | K7: =IFERROR(VLOOKUP(B7,'6. AUTH'!A:N,10,FALSE()),"") | L7: =IFERROR(VLOOKUP(B7,'6. AUTH'!A:N,11,FALSE()),"") | M7: =IFERROR(VLOOKUP(B7,'6. AUTH'!A:N,12,FALSE()),"") | N7: =IFERROR(VLOOKUP(B7,'6. AUTH'!A:N,13,FALSE()),"") | O7: =IFERROR(VLOOKUP(B7,'6. AUTH'!A:N,14,FALSE()),"")
A8: AUTH | B8: CT-AUTH-005 | C8: Connexion refusée — mauvais mot de passe | D8: Intégration | E8: Bloquant | F8: — | G8: — | H8: POST /api/auth/login avec mauvais mot de passe | I8: HTTP 401 + body.error « Email ou mot de passe incorrect » (message identique pour email inconnu, anti-énumération) | J8: ✅ | K8: =IFERROR(VLOOKUP(B8,'6. AUTH'!A:N,10,FALSE()),"") | L8: =IFERROR(VLOOKUP(B8,'6. AUTH'!A:N,11,FALSE()),"") | M8: =IFERROR(VLOOKUP(B8,'6. AUTH'!A:N,12,FALSE()),"") | N8: =IFERROR(VLOOKUP(B8,'6. AUTH'!A:N,13,FALSE()),"") | O8: =IFERROR(VLOOKUP(B8,'6. AUTH'!A:N,14,FALSE()),"")
A9: AUTH | B9: CT-AUTH-006 | C9: Connexion refusée — email inconnu | D9: Intégration | E9: Bloquant | F9: — | G9: — | H9: POST /api/auth/login avec email jamais inscrit | I9: HTTP 401 + même message qu'au CT-AUTH-005 | J9: ✅ | K9: =IFERROR(VLOOKUP(B9,'6. AUTH'!A:N,10,FALSE()),"") | L9: =IFERROR(VLOOKUP(B9,'6. AUTH'!A:N,11,FALSE()),"") | M9: =IFERROR(VLOOKUP(B9,'6. AUTH'!A:N,12,FALSE()),"") | N9: =IFERROR(VLOOKUP(B9,'6. AUTH'!A:N,13,FALSE()),"") | O9: =IFERROR(VLOOKUP(B9,'6. AUTH'!A:N,14,FALSE()),"")
A10: AUTH | B10: CT-AUTH-007 | C10: Connexion refusée — compte banni | D10: Intégration | E10: Haute | F10: banned@test.com avec isBanned=true | G10: — | H10: POST /api/auth/login | I10: HTTP 403 + body.error contient « suspendu » | J10: ✅ | K10: =IFERROR(VLOOKUP(B10,'6. AUTH'!A:N,10,FALSE()),"") | L10: =IFERROR(VLOOKUP(B10,'6. AUTH'!A:N,11,FALSE()),"") | M10: =IFERROR(VLOOKUP(B10,'6. AUTH'!A:N,12,FALSE()),"") | N10: =IFERROR(VLOOKUP(B10,'6. AUTH'!A:N,13,FALSE()),"") | O10: =IFERROR(VLOOKUP(B10,'6. AUTH'!A:N,14,FALSE()),"")
A11: AUTH | B11: CT-AUTH-008 | C11: /api/auth/me sans authentification | D11: Intégration | E11: Moyenne | F11: — | G11: — | H11: GET /api/auth/me sans cookie ni Bearer | I11: HTTP 200 + body = null | J11: ✅ | K11: =IFERROR(VLOOKUP(B11,'6. AUTH'!A:N,10,FALSE()),"") | L11: =IFERROR(VLOOKUP(B11,'6. AUTH'!A:N,11,FALSE()),"") | M11: =IFERROR(VLOOKUP(B11,'6. AUTH'!A:N,12,FALSE()),"") | N11: =IFERROR(VLOOKUP(B11,'6. AUTH'!A:N,13,FALSE()),"") | O11: =IFERROR(VLOOKUP(B11,'6. AUTH'!A:N,14,FALSE()),"")
A12: AUTH | B12: CT-AUTH-009 | C12: /api/auth/me avec Bearer valide (mobile) | D12: Intégration | E12: Bloquant | F12: — | G12: JWT valide | H12: GET /api/auth/me avec Authorization: Bearer <jwt> | I12: HTTP 200 + body contient userId, email, role | J12: ✅ | K12: =IFERROR(VLOOKUP(B12,'6. AUTH'!A:N,10,FALSE()),"") | L12: =IFERROR(VLOOKUP(B12,'6. AUTH'!A:N,11,FALSE()),"") | M12: =IFERROR(VLOOKUP(B12,'6. AUTH'!A:N,12,FALSE()),"") | N12: =IFERROR(VLOOKUP(B12,'6. AUTH'!A:N,13,FALSE()),"") | O12: =IFERROR(VLOOKUP(B12,'6. AUTH'!A:N,14,FALSE()),"")
A13: AUTH | B13: CT-AUTH-010 | C13: /api/auth/me avec Bearer altéré | D13: Intégration | E13: Bloquant | F13: — | G13: JWT avec signature modifiée | H13: GET /api/auth/me avec un JWT dont la signature est modifiée | I13: HTTP 200 + body = null (jose rejette silencieusement) | J13: ✅ | K13: =IFERROR(VLOOKUP(B13,'6. AUTH'!A:N,10,FALSE()),"") | L13: =IFERROR(VLOOKUP(B13,'6. AUTH'!A:N,11,FALSE()),"") | M13: =IFERROR(VLOOKUP(B13,'6. AUTH'!A:N,12,FALSE()),"") | N13: =IFERROR(VLOOKUP(B13,'6. AUTH'!A:N,13,FALSE()),"") | O13: =IFERROR(VLOOKUP(B13,'6. AUTH'!A:N,14,FALSE()),"")
A14: AUTH | B14: CT-AUTH-011 | C14: Logout web | D14: Intégration | E14: Haute | F14: Cookie session présent | G14: — | H14: POST /api/auth/logout | I14: HTTP 200 + Set-Cookie supprimant session | J14: ✅ | K14: =IFERROR(VLOOKUP(B14,'6. AUTH'!A:N,10,FALSE()),"") | L14: =IFERROR(VLOOKUP(B14,'6. AUTH'!A:N,11,FALSE()),"") | M14: =IFERROR(VLOOKUP(B14,'6. AUTH'!A:N,12,FALSE()),"") | N14: =IFERROR(VLOOKUP(B14,'6. AUTH'!A:N,13,FALSE()),"") | O14: =IFERROR(VLOOKUP(B14,'6. AUTH'!A:N,14,FALSE()),"")
A15: AUTH | B15: CT-AUTH-012 | C15: Logout mobile (best-effort) | D15: E2E | E15: Moyenne | F15: App mobile authentifiée | G15: — | H15: App mobile : tap « Se déconnecter » | I15: • POST /api/auth/logout envoyé • expo-secure-store ne contient plus cesizen_token • Redirection vers écran login | J15: ✅ Maestro 06-logout.yaml + Jest AuthContext.test.tsx | K15: =IFERROR(VLOOKUP(B15,'6. AUTH'!A:N,10,FALSE()),"") | L15: =IFERROR(VLOOKUP(B15,'6. AUTH'!A:N,11,FALSE()),"") | M15: =IFERROR(VLOOKUP(B15,'6. AUTH'!A:N,12,FALSE()),"") | N15: =IFERROR(VLOOKUP(B15,'6. AUTH'!A:N,13,FALSE()),"") | O15: =IFERROR(VLOOKUP(B15,'6. AUTH'!A:N,14,FALSE()),"")
... A18: AUTH | B18: CT-AUTH-015 | C18: confirmPassword ne correspond pas | D18: Intégration | E18: Haute | F18: — | G18: password=Password1, confirmPassword=Password2 | H18: register avec mots de passe différents | I18: HTTP 400 + fieldErrors.confirmPassword | J18: ✅ | K18: =IFERROR(VLOOKUP(B18,'6. AUTH'!A:N,10,FALSE()),"") | L18: =IFERROR(VLOOKUP(B18,'6. AUTH'!A:N,11,FALSE()),"") | M18: =IFERROR(VLOOKUP(B18,'6. AUTH'!A:N,12,FALSE()),"") | N18: =IFERROR(VLOOKUP(B18,'6. AUTH'!A:N,13,FALSE()),"") | O18: =IFERROR(VLOOKUP(B18,'6. AUTH'!A:N,14,FALSE()),"")
A19: JRN | B19: CT-JRN-001 | C19: Création d'une entrée minimale (sans note ni tags) | D19: Intégration | E19: Bloquant | F19: User authentifié, émotion id=1 existe | G19: { emotionId: 1, intensity: 5 } | H19: POST /api/entries | I19: HTTP 200 + ligne entries créée avec userId, emotionId, intensity, noteEncrypted=null, contextTags=[] | J19: ✅ | K19: =IFERROR(VLOOKUP(B19,'7. JRN'!A:N,10,FALSE()),"") | L19: =IFERROR(VLOOKUP(B19,'7. JRN'!A:N,11,FALSE()),"") | M19: =IFERROR(VLOOKUP(B19,'7. JRN'!A:N,12,FALSE()),"") | N19: =IFERROR(VLOOKUP(B19,'7. JRN'!A:N,13,FALSE()),"") | O19: =IFERROR(VLOOKUP(B19,'7. JRN'!A:N,14,FALSE()),"")
A20: JRN | B20: CT-JRN-002 | C20: Création d'une entrée complète (note + tags) | D20: Intégration | E20: Bloquant | F20: User authentifié | G20: emotionId=1, intensity=7, note='Ma note privée', contextTags=['travail','sommeil'] | H20: POST /api/entries | I20: • HTTP 200 • En DB : noteEncrypted au format iv:tag:cipher (pas en clair) • contextTags = tableau des 2 tags | J20: ✅ | K20: =IFERROR(VLOOKUP(B20,'7. JRN'!A:N,10,FALSE()),"") | L20: =IFERROR(VLOOKUP(B20,'7. JRN'!A:N,11,FALSE()),"") | M20: =IFERROR(VLOOKUP(B20,'7. JRN'!A:N,12,FALSE()),"") | N20: =IFERROR(VLOOKUP(B20,'7. JRN'!A:N,13,FALSE()),"") | O20: =IFERROR(VLOOKUP(B20,'7. JRN'!A:N,14,FALSE()),"")
A21: JRN | B21: CT-JRN-003 | C21: Lecture des entrées (note déchiffrée) | D21: Intégration | E21: Bloquant | F21: Suite à CT-JRN-002 | G21: — | H21: GET /api/entries | I21: • HTTP 200 • body[0].note === 'Ma note privée' (déchiffré) • body[0].noteEncrypted === undefined (strippé) | J21: ✅ | K21: =IFERROR(VLOOKUP(B21,'7. JRN'!A:N,10,FALSE()),"") | L21: =IFERROR(VLOOKUP(B21,'7. JRN'!A:N,11,FALSE()),"") | M21: =IFERROR(VLOOKUP(B21,'7. JRN'!A:N,12,FALSE()),"") | N21: =IFERROR(VLOOKUP(B21,'7. JRN'!A:N,13,FALSE()),"") | O21: =IFERROR(VLOOKUP(B21,'7. JRN'!A:N,14,FALSE()),"")
A22: JRN | B22: CT-JRN-004 | C22: Lecture filtrée par dates | D22: Intégration | E22: Haute | F22: Plusieurs entrées en base | G22: startDate, endDate | H22: GET /api/entries?startDate=...&endDate=... | I22: Seules les entrées dans la fenêtre sont retournées | J22: ✅ | K22: =IFERROR(VLOOKUP(B22,'7. JRN'!A:N,10,FALSE()),"") | L22: =IFERROR(VLOOKUP(B22,'7. JRN'!A:N,11,FALSE()),"") | M22: =IFERROR(VLOOKUP(B22,'7. JRN'!A:N,12,FALSE()),"") | N22: =IFERROR(VLOOKUP(B22,'7. JRN'!A:N,13,FALSE()),"") | O22: =IFERROR(VLOOKUP(B22,'7. JRN'!A:N,14,FALSE()),"")
A23: JRN | B23: CT-JRN-005 | C23: Note stockée chiffrée en DB | D23: Intégration | E23: Bloquant (sécurité) | F23: — | G23: note='secret' | H23: • Créer entrée avec note 'secret' • Lire entries.note_encrypted directement en SQL | I23: • Pas de 'secret' en clair • Format iv:tag:cipher (3 parties hex séparées par :) | J23: ✅ via encryption.test.ts + entries.test.ts | K23: =IFERROR(VLOOKUP(B23,'7. JRN'!A:N,10,FALSE()),"") | L23: =IFERROR(VLOOKUP(B23,'7. JRN'!A:N,11,FALSE()),"") | M23: =IFERROR(VLOOKUP(B23,'7. JRN'!A:N,12,FALSE()),"") | N23: =IFERROR(VLOOKUP(B23,'7. JRN'!A:N,13,FALSE()),"") | O23: =IFERROR(VLOOKUP(B23,'7. JRN'!A:N,14,FALSE()),"")
A24: JRN | B24: CT-JRN-006 | C24: Intensité < 1 rejetée | D24: Intégration | E24: Haute | F24: — | G24: { emotionId: 1, intensity: 0 } | H24: POST /api/entries | I24: HTTP 400 + fieldErrors.intensity | J24: ✅ | K24: =IFERROR(VLOOKUP(B24,'7. JRN'!A:N,10,FALSE()),"") | L24: =IFERROR(VLOOKUP(B24,'7. JRN'!A:N,11,FALSE()),"") | M24: =IFERROR(VLOOKUP(B24,'7. JRN'!A:N,12,FALSE()),"") | N24: =IFERROR(VLOOKUP(B24,'7. JRN'!A:N,13,FALSE()),"") | O24: =IFERROR(VLOOKUP(B24,'7. JRN'!A:N,14,FALSE()),"")
A25: JRN | B25: CT-JRN-007 | C25: Intensité > 10 rejetée | D25: Intégration | E25: Haute | F25: — | G25: { emotionId: 1, intensity: 99 } | H25: POST /api/entries | I25: HTTP 400 | J25: ✅ | K25: =IFERROR(VLOOKUP(B25,'7. JRN'!A:N,10,FALSE()),"") | L25: =IFERROR(VLOOKUP(B25,'7. JRN'!A:N,11,FALSE()),"") | M25: =IFERROR(VLOOKUP(B25,'7. JRN'!A:N,12,FALSE()),"") | N25: =IFERROR(VLOOKUP(B25,'7. JRN'!A:N,13,FALSE()),"") | O25: =IFERROR(VLOOKUP(B25,'7. JRN'!A:N,14,FALSE()),"")
A26: JRN | B26: CT-JRN-008 | C26: Note > 2000 caractères rejetée | D26: Intégration | E26: Moyenne | F26: — | G26: note = 'x'.repeat(2001) | H26: POST /api/entries | I26: HTTP 400 + fieldErrors.note | J26: ✅ | K26: =IFERROR(VLOOKUP(B26,'7. JRN'!A:N,10,FALSE()),"") | L26: =IFERROR(VLOOKUP(B26,'7. JRN'!A:N,11,FALSE()),"") | M26: =IFERROR(VLOOKUP(B26,'7. JRN'!A:N,12,FALSE()),"") | N26: =IFERROR(VLOOKUP(B26,'7. JRN'!A:N,13,FALSE()),"") | O26: =IFERROR(VLOOKUP(B26,'7. JRN'!A:N,14,FALSE()),"")
A27: JRN | B27: CT-JRN-009 | C27: Ownership : un user ne voit pas les entrées d'un autre | D27: Intégration | E27: Bloquant (sécurité) | F27: userA a 1 entrée, userB authentifié | G27: — | H27: GET /api/entries avec token de userB | I27: body = [] (pas d'entrée de userA) | J27: ✅ | K27: =IFERROR(VLOOKUP(B27,'7. JRN'!A:N,10,FALSE()),"") | L27: =IFERROR(VLOOKUP(B27,'7. JRN'!A:N,11,FALSE()),"") | M27: =IFERROR(VLOOKUP(B27,'7. JRN'!A:N,12,FALSE()),"") | N27: =IFERROR(VLOOKUP(B27,'7. JRN'!A:N,13,FALSE()),"") | O27: =IFERROR(VLOOKUP(B27,'7. JRN'!A:N,14,FALSE()),"")
A28: JRN | B28: CT-JRN-010 | C28: Ownership : GET d'une entrée d'un autre user → 404 | D28: Intégration | E28: Bloquant (sécurité) | F28: Entrée existante de userA | G28: id de l'entrée userA | H28: GET /api/entries/[idDeUserA] avec token de userB | I28: HTTP 404 (pas 403, pour ne pas révéler l'existence) | J28: ✅ | K28: =IFERROR(VLOOKUP(B28,'7. JRN'!A:N,10,FALSE()),"") | L28: =IFERROR(VLOOKUP(B28,'7. JRN'!A:N,11,FALSE()),"") | M28: =IFERROR(VLOOKUP(B28,'7. JRN'!A:N,12,FALSE()),"") | N28: =IFERROR(VLOOKUP(B28,'7. JRN'!A:N,13,FALSE()),"") | O28: =IFERROR(VLOOKUP(B28,'7. JRN'!A:N,14,FALSE()),"")
A29: JRN | B29: CT-JRN-011 | C29: Édition d'une entrée | D29: Intégration | E29: Haute | F29: Entrée existante du user | G29: Nouvelles valeurs | H29: PUT /api/entries/[id] avec nouvelles valeurs | I29: HTTP 200 + entrée modifiée + noteEncrypted ré-encrypté | J29: ✅ | K29: =IFERROR(VLOOKUP(B29,'7. JRN'!A:N,10,FALSE()),"") | L29: =IFERROR(VLOOKUP(B29,'7. JRN'!A:N,11,FALSE()),"") | M29: =IFERROR(VLOOKUP(B29,'7. JRN'!A:N,12,FALSE()),"") | N29: =IFERROR(VLOOKUP(B29,'7. JRN'!A:N,13,FALSE()),"") | O29: =IFERROR(VLOOKUP(B29,'7. JRN'!A:N,14,FALSE()),"")
A30: JRN | B30: CT-JRN-012 | C30: Édition d'une entrée d'un autre user → 404 | D30: Intégration | E30: Bloquant (sécurité) | F30: Entrée existante de userA | G30: — | H30: PUT /api/entries/[idDeUserA] avec token de userB | I30: HTTP 404, aucune modification en DB | J30: ✅ | K30: =IFERROR(VLOOKUP(B30,'7. JRN'!A:N,10,FALSE()),"") | L30: =IFERROR(VLOOKUP(B30,'7. JRN'!A:N,11,FALSE()),"") | M30: =IFERROR(VLOOKUP(B30,'7. JRN'!A:N,12,FALSE()),"") | N30: =IFERROR(VLOOKUP(B30,'7. JRN'!A:N,13,FALSE()),"") | O30: =IFERROR(VLOOKUP(B30,'7. JRN'!A:N,14,FALSE()),"")
... A38: JRN | B38: CT-JRN-020 | C38: Mobile : édition + suppression | D38: Manuel | E38: Haute | F38: Une entrée existante | G38: — | H38: Tap entrée → modifier → sauver, puis supprimer avec alert | I38: Modification persistée puis entrée disparaît | J38: Manuel | K38: =IFERROR(VLOOKUP(B38,'7. JRN'!A:N,10,FALSE()),"") | L38: =IFERROR(VLOOKUP(B38,'7. JRN'!A:N,11,FALSE()),"") | M38: =IFERROR(VLOOKUP(B38,'7. JRN'!A:N,12,FALSE()),"") | N38: =IFERROR(VLOOKUP(B38,'7. JRN'!A:N,13,FALSE()),"") | O38: =IFERROR(VLOOKUP(B38,'7. JRN'!A:N,14,FALSE()),"")
A39: STAT | B39: CT-STAT-001 | C39: Stats vides (0 entrée) | D39: Intégration | E39: Moyenne | F39: User sans entrée | G39: — | H39: GET /api/entries/stats | I39: totalEntries=0, dailyAverages=[], recentEntries=[] (pas d'erreur) | J39: À ajouter | K39: =IFERROR(VLOOKUP(B39,'8. STAT'!A:N,10,FALSE()),"") | L39: =IFERROR(VLOOKUP(B39,'8. STAT'!A:N,11,FALSE()),"") | M39: =IFERROR(VLOOKUP(B39,'8. STAT'!A:N,12,FALSE()),"") | N39: =IFERROR(VLOOKUP(B39,'8. STAT'!A:N,13,FALSE()),"") | O39: =IFERROR(VLOOKUP(B39,'8. STAT'!A:N,14,FALSE()),"")
A40: STAT | B40: CT-STAT-002 | C40: Stats nominales sur 30 jours | D40: Intégration | E40: Haute | F40: 3 entrées dans les 30 jours | G40: — | H40: GET /api/entries/stats | I40: totalEntries=3, dailyAverages avec moyenne par jour | J40: ✅ | K40: =IFERROR(VLOOKUP(B40,'8. STAT'!A:N,10,FALSE()),"") | L40: =IFERROR(VLOOKUP(B40,'8. STAT'!A:N,11,FALSE()),"") | M40: =IFERROR(VLOOKUP(B40,'8. STAT'!A:N,12,FALSE()),"") | N40: =IFERROR(VLOOKUP(B40,'8. STAT'!A:N,13,FALSE()),"") | O40: =IFERROR(VLOOKUP(B40,'8. STAT'!A:N,14,FALSE()),"")
A41: STAT | B41: CT-STAT-003 | C41: detailed-stats sans bornes → 400 | D41: Intégration | E41: Moyenne | F41: — | G41: — | H41: GET /api/entries/detailed-stats sans paramètres | I41: HTTP 400 | J41: ✅ | K41: =IFERROR(VLOOKUP(B41,'8. STAT'!A:N,10,FALSE()),"") | L41: =IFERROR(VLOOKUP(B41,'8. STAT'!A:N,11,FALSE()),"") | M41: =IFERROR(VLOOKUP(B41,'8. STAT'!A:N,12,FALSE()),"") | N41: =IFERROR(VLOOKUP(B41,'8. STAT'!A:N,13,FALSE()),"") | O41: =IFERROR(VLOOKUP(B41,'8. STAT'!A:N,14,FALSE()),"")
A42: STAT | B42: CT-STAT-004 | C42: detailed-stats — agrégats complets | D42: Intégration | E42: Haute | F42: Historique d'entrées | G42: startDate, endDate | H42: GET /api/entries/detailed-stats?startDate=...&endDate=... | I42: • totalEntries, averageIntensity • mostFrequentEmotion / Category • emotionDistribution[] et categoryDistribution[] • dailyAverages[] • weekdayDistribution[7], hourDistribution[24] • streakDays • contextTagsDistribution[] | J42: ✅ | K42: =IFERROR(VLOOKUP(B42,'8. STAT'!A:N,10,FALSE()),"") | L42: =IFERROR(VLOOKUP(B42,'8. STAT'!A:N,11,FALSE()),"") | M42: =IFERROR(VLOOKUP(B42,'8. STAT'!A:N,12,FALSE()),"") | N42: =IFERROR(VLOOKUP(B42,'8. STAT'!A:N,13,FALSE()),"") | O42: =IFERROR(VLOOKUP(B42,'8. STAT'!A:N,14,FALSE()),"")
A43: STAT | B43: CT-STAT-005 | C43: Streak de jours consécutifs | D43: Intégration | E43: Moyenne | F43: 3 entrées sur 3 jours consécutifs, puis trou de 5 jours, puis 2 entrées sur 2 jours | G43: — | H43: GET /api/entries/detailed-stats | I43: streakDays = 3 (max) | J43: À ajouter | K43: =IFERROR(VLOOKUP(B43,'8. STAT'!A:N,10,FALSE()),"") | L43: =IFERROR(VLOOKUP(B43,'8. STAT'!A:N,11,FALSE()),"") | M43: =IFERROR(VLOOKUP(B43,'8. STAT'!A:N,12,FALSE()),"") | N43: =IFERROR(VLOOKUP(B43,'8. STAT'!A:N,13,FALSE()),"") | O43: =IFERROR(VLOOKUP(B43,'8. STAT'!A:N,14,FALSE()),"")
A44: STAT | B44: CT-STAT-006 | C44: Distribution par jour de la semaine | D44: Intégration | E44: Moyenne | F44: — | G44: 5 entrées un lundi | H44: Créer 5 entrées un lundi puis GET stats | I44: weekdayDistribution[1].count = 5, percentage = 100 | J44: À ajouter | K44: =IFERROR(VLOOKUP(B44,'8. STAT'!A:N,10,FALSE()),"") | L44: =IFERROR(VLOOKUP(B44,'8. STAT'!A:N,11,FALSE()),"") | M44: =IFERROR(VLOOKUP(B44,'8. STAT'!A:N,12,FALSE()),"") | N44: =IFERROR(VLOOKUP(B44,'8. STAT'!A:N,13,FALSE()),"") | O44: =IFERROR(VLOOKUP(B44,'8. STAT'!A:N,14,FALSE()),"")
A45: STAT | B45: CT-STAT-007 | C45: Web : sélecteur de période | D45: E2E | E45: Haute | F45: Compte avec historique | G45: — | H45: /dashboard/statistiques → cliquer 'Cette semaine' puis 'Mois dernier' | I45: Refetch + KPI mis à jour | J45: Manuel | K45: =IFERROR(VLOOKUP(B45,'8. STAT'!A:N,10,FALSE()),"") | L45: =IFERROR(VLOOKUP(B45,'8. STAT'!A:N,11,FALSE()),"") | M45: =IFERROR(VLOOKUP(B45,'8. STAT'!A:N,12,FALSE()),"") | N45: =IFERROR(VLOOKUP(B45,'8. STAT'!A:N,13,FALSE()),"") | O45: =IFERROR(VLOOKUP(B45,'8. STAT'!A:N,14,FALSE()),"")
A46: STAT | B46: CT-STAT-008 | C46: Mobile : bascule 7j / 30j / 90j | D46: E2E Maestro | E46: Haute | F46: Compte avec historique | G46: — | H46: Onglet Stats → switch périodes | I46: Données cohérentes selon période | J46: ✅ 05-statistiques.yaml | K46: =IFERROR(VLOOKUP(B46,'8. STAT'!A:N,10,FALSE()),"") | L46: =IFERROR(VLOOKUP(B46,'8. STAT'!A:N,11,FALSE()),"") | M46: =IFERROR(VLOOKUP(B46,'8. STAT'!A:N,12,FALSE()),"") | N46: =IFERROR(VLOOKUP(B46,'8. STAT'!A:N,13,FALSE()),"") | O46: =IFERROR(VLOOKUP(B46,'8. STAT'!A:N,14,FALSE()),"")
A47: CONS | B47: CT-CONS-001 | C47: Liste publique des articles publiés | D47: Intégration | E47: Haute | F47: Articles publiés en DB | G47: — | H47: GET /api/articles?publishedOnly=true | I47: Seuls les articles avec isPublished=true | J47: ✅ | K47: =IFERROR(VLOOKUP(B47,'9. CONS'!A:N,10,FALSE()),"") | L47: =IFERROR(VLOOKUP(B47,'9. CONS'!A:N,11,FALSE()),"") | M47: =IFERROR(VLOOKUP(B47,'9. CONS'!A:N,12,FALSE()),"") | N47: =IFERROR(VLOOKUP(B47,'9. CONS'!A:N,13,FALSE()),"") | O47: =IFERROR(VLOOKUP(B47,'9. CONS'!A:N,14,FALSE()),"")
A48: CONS | B48: CT-CONS-002 | C48: Liste sans filtre (admin) | D48: Intégration | E48: Moyenne | F48: Articles publiés + brouillons | G48: — | H48: GET /api/articles | I48: Tous les articles (drafts inclus) | J48: ✅ | K48: =IFERROR(VLOOKUP(B48,'9. CONS'!A:N,10,FALSE()),"") | L48: =IFERROR(VLOOKUP(B48,'9. CONS'!A:N,11,FALSE()),"") | M48: =IFERROR(VLOOKUP(B48,'9. CONS'!A:N,12,FALSE()),"") | N48: =IFERROR(VLOOKUP(B48,'9. CONS'!A:N,13,FALSE()),"") | O48: =IFERROR(VLOOKUP(B48,'9. CONS'!A:N,14,FALSE()),"")
A49: CONS | B49: CT-CONS-003 | C49: Lookup par slug existant | D49: Intégration | E49: Haute | F49: Article slug='hello' | G49: — | H49: GET /api/articles/by-slug/hello | I49: HTTP 200 + article complet | J49: ✅ | K49: =IFERROR(VLOOKUP(B49,'9. CONS'!A:N,10,FALSE()),"") | L49: =IFERROR(VLOOKUP(B49,'9. CONS'!A:N,11,FALSE()),"") | M49: =IFERROR(VLOOKUP(B49,'9. CONS'!A:N,12,FALSE()),"") | N49: =IFERROR(VLOOKUP(B49,'9. CONS'!A:N,13,FALSE()),"") | O49: =IFERROR(VLOOKUP(B49,'9. CONS'!A:N,14,FALSE()),"")
...

Sheet 6. AUTH
A1: 6. Cas de test — AUTH (Authentification)
A3: ID | B3: Titre | C3: Niveau | D3: Criticité | E3: Préconditions | F3: Données | G3: Étapes | H3: Résultat attendu | I3: Automatisé | J3: Statut | K3: Date exécution | L3: Testeur | M3: Commentaire | N3: ID anomalie
A4: CT-AUTH-001 | B4: Inscription nominale | C4: Intégration | D4: Bloquant | E4: Aucun compte avec l'email cible n'existe en DB | F4: email=new@test.com, password=Password1, confirm=Password1, prenom=Jane, nom=Doe | G4: 1. POST /api/auth/register avec le body 2. Lire la réponse | H4: • HTTP 200 • body.success === true • body.token au format JWT (3 segments séparés par .) • Cookie session posé httpOnly + sameSite=lax • Ligne créée dans users avec role='user' et isBanned=false | I4: ✅ tests/integration/auth.test.ts | J4: À exécuter
A5: CT-AUTH-002 | B5: Inscription rejetée pour mot de passe faible | C5: Intégration | D5: Haute | E5: — | F5: email=a@b.co, password=short, confirm=short | G5: POST /api/auth/register | H5: HTTP 400 + body.fieldErrors.password non vide (regex maj/min/chiffre/8 car) | I5: ✅ | J5: À exécuter
A6: CT-AUTH-003 | B6: Inscription rejetée pour email déjà utilisé | C6: Intégration | D6: Haute | E6: Un user dup@test.com existe | F6: email=dup@test.com | G6: POST /api/auth/register avec ce même email | H6: HTTP 409 + body.error contient « existe déjà » | I6: ✅ | J6: À exécuter
A7: CT-AUTH-004 | B7: Connexion nominale | C7: Intégration | D7: Bloquant | E7: Compte log@test.com / Password123 actif | F7: — | G7: POST /api/auth/login | H7: HTTP 200 + token JWT + cookie session posé | I7: ✅ | J7: À exécuter
A8: CT-AUTH-005 | B8: Connexion refusée — mauvais mot de passe | C8: Intégration | D8: Bloquant | E8: — | F8: — | G8: POST /api/auth/login avec mauvais mot de passe | H8: HTTP 401 + body.error « Email ou mot de passe incorrect » (message identique pour email inconnu, anti-énumération) | I8: ✅ | J8: À exécuter
A9: CT-AUTH-006 | B9: Connexion refusée — email inconnu | C9: Intégration | D9: Bloquant | E9: — | F9: — | G9: POST /api/auth/login avec email jamais inscrit | H9: HTTP 401 + même message qu'au CT-AUTH-005 | I9: ✅ | J9: À exécuter
A10: CT-AUTH-007 | B10: Connexion refusée — compte banni | C10: Intégration | D10: Haute | E10: banned@test.com avec isBanned=true | F10: — | G10: POST /api/auth/login | H10: HTTP 403 + body.error contient « suspendu » | I10: ✅ | J10: À exécuter
A11: CT-AUTH-008 | B11: /api/auth/me sans authentification | C11: Intégration | D11: Moyenne | E11: — | F11: — | G11: GET /api/auth/me sans cookie ni Bearer | H11: HTTP 200 + body = null | I11: ✅ | J11: À exécuter
A12: CT-AUTH-009 | B12: /api/auth/me avec Bearer valide (mobile) | C12: Intégration | D12: Bloquant | E12: — | F12: JWT valide | G12: GET /api/auth/me avec Authorization: Bearer <jwt> | H12: HTTP 200 + body contient userId, email, role | I12: ✅ | J12: À exécuter
A13: CT-AUTH-010 | B13: /api/auth/me avec Bearer altéré | C13: Intégration | D13: Bloquant | E13: — | F13: JWT avec signature modifiée | G13: GET /api/auth/me avec un JWT dont la signature est modifiée | H13: HTTP 200 + body = null (jose rejette silencieusement) | I13: ✅ | J13: À exécuter
A14: CT-AUTH-011 | B14: Logout web | C14: Intégration | D14: Haute | E14: Cookie session présent | F14: — | G14: POST /api/auth/logout | H14: HTTP 200 + Set-Cookie supprimant session | I14: ✅ | J14: À exécuter
A15: CT-AUTH-012 | B15: Logout mobile (best-effort) | C15: E2E | D15: Moyenne | E15: App mobile authentifiée | F15: — | G15: App mobile : tap « Se déconnecter » | H15: • POST /api/auth/logout envoyé • expo-secure-store ne contient plus cesizen_token • Redirection vers écran login | I15: ✅ Maestro 06-logout.yaml + Jest AuthContext.test.tsx | J15: À exécuter
... A20: CT-AUTH-017 | B20: getSession → null si cookie JWT invalide | C20: Unitaire | D20: Haute | E20: Cookie session posé avec valeur JWT invalide | F20: cookie='invalid-jwt-token' | G20: getSession() | H20: Retourne null (pas d'exception levée) | I20: ✅ tests/unit/session.test.ts | J20: À exécuter

Sheet 7. JRN
A1: 7. Cas de test — JRN (Journal émotionnel)
A3: ID | B3: Titre | C3: Niveau | D3: Criticité | E3: Préconditions | F3: Données | G3: Étapes | H3: Résultat attendu | I3: Automatisé | J3: Statut | K3: Date exécution | L3: Testeur | M3: Commentaire | N3: ID anomalie
A4: CT-JRN-001 | B4: Création d'une entrée minimale (sans note ni tags) | C4: Intégration | D4: Bloquant | E4: User authentifié, émotion id=1 existe | F4: { emotionId: 1, intensity: 5 } | G4: POST /api/entries | H4: HTTP 200 + ligne entries créée avec userId, emotionId, intensity, noteEncrypted=null, contextTags=[] | I4: ✅ | J4: À exécuter
A5: CT-JRN-002 | B5: Création d'une entrée complète (note + tags) | C5: Intégration | D5: Bloquant | E5: User authentifié | F5: emotionId=1, intensity=7, note='Ma note privée', contextTags=['travail','sommeil'] | G5: POST /api/entries | H5: • HTTP 200 • En DB : noteEncrypted au format iv:tag:cipher (pas en clair) • contextTags = tableau des 2 tags | I5: ✅ | J5: À exécuter
A6: CT-JRN-003 | B6: Lecture des entrées (note déchiffrée) | C6: Intégration | D6: Bloquant | E6: Suite à CT-JRN-002 | F6: — | G6: GET /api/entries | H6: • HTTP 200 • body[0].note === 'Ma note privée' (déchiffré) • body[0].noteEncrypted === undefined (strippé) | I6: ✅ | J6: À exécuter
A7: CT-JRN-004 | B7: Lecture filtrée par dates | C7: Intégration | D7: Haute | E7: Plusieurs entrées en base | F7: startDate, endDate | G7: GET /api/entries?startDate=...&endDate=... | H7: Seules les entrées dans la fenêtre sont retournées | I7: ✅ | J7: À exécuter
A8: CT-JRN-005 | B8: Note stockée chiffrée en DB | C8: Intégration | D8: Bloquant (sécurité) | E8: — | F8: note='secret' | G8: • Créer entrée avec note 'secret' • Lire entries.note_encrypted directement en SQL | H8: • Pas de 'secret' en clair • Format iv:tag:cipher (3 parties hex séparées par :) | I8: ✅ via encryption.test.ts + entries.test.ts | J8: À exécuter
A9: CT-JRN-006 | B9: Intensité < 1 rejetée | C9: Intégration | D9: Haute | E9: — | F9: { emotionId: 1, intensity: 0 } | G9: POST /api/entries | H9: HTTP 400 + fieldErrors.intensity | I9: ✅ | J9: À exécuter
A10: CT-JRN-007 | B10: Intensité > 10 rejetée | C10: Intégration | D10: Haute | E10: — | F10: { emotionId: 1, intensity: 99 } | G10: POST /api/entries | H10: HTTP 400 | I10: ✅ | J10: À exécuter
A11: CT-JRN-008 | B11: Note > 2000 caractères rejetée | C11: Intégration | D11: Moyenne | E11: — | F11: note = 'x'.repeat(2001) | G11: POST /api/entries | H11: HTTP 400 + fieldErrors.note | I11: ✅ | J11: À exécuter
A12: CT-JRN-009 | B12: Ownership : un user ne voit pas les entrées d'un autre | C12: Intégration | D12: Bloquant (sécurité) | E12: userA a 1 entrée, userB authentifié | F12: — | G12: GET /api/entries avec token de userB | H12: body = [] (pas d'entrée de userA) | I12: ✅ | J12: À exécuter
A13: CT-JRN-010 | B13: Ownership : GET d'une entrée d'un autre user → 404 | C13: Intégration | D13: Bloquant (sécurité) | E13: Entrée existante de userA | F13: id de l'entrée userA | G13: GET /api/entries/[idDeUserA] avec token de userB | H13: HTTP 404 (pas 403, pour ne pas révéler l'existence) | I13: ✅ | J13: À exécuter
A14: CT-JRN-011 | B14: Édition d'une entrée | C14: Intégration | D14: Haute | E14: Entrée existante du user | F14: Nouvelles valeurs | G14: PUT /api/entries/[id] avec nouvelles valeurs | H14: HTTP 200 + entrée modifiée + noteEncrypted ré-encrypté | I14: ✅ | J14: À exécuter
A15: CT-JRN-012 | B15: Édition d'une entrée d'un autre user → 404 | C15: Intégration | D15: Bloquant (sécurité) | E15: Entrée existante de userA | F15: — | G15: PUT /api/entries/[idDeUserA] avec token de userB | H15: HTTP 404, aucune modification en DB | I15: ✅ | J15: À exécuter
... A30: CT-JRN-027 | B30: PUT /api/entries/[id] → 400 validation (intensity hors plage) | C30: Intégration | D30: Haute | E30: User authentifié, entrée existante | F30: { emotionId: 1, intensity: 99 } | G30: PUT /api/entries/[id] | H30: HTTP 400 | I30: ✅ tests/integration/entries.test.ts | J30: À exécuter

Sheet 8. STAT
A1: 8. Cas de test — STAT (Statistiques)
A3: ID | B3: Titre | C3: Niveau | D3: Criticité | E3: Préconditions | F3: Données | G3: Étapes | H3: Résultat attendu | I3: Automatisé | J3: Statut | K3: Date exécution | L3: Testeur | M3: Commentaire | N3: ID anomalie
A4: CT-STAT-001 | B4: Stats vides (0 entrée) | C4: Intégration | D4: Moyenne | E4: User sans entrée | F4: — | G4: GET /api/entries/stats | H4: totalEntries=0, dailyAverages=[], recentEntries=[] (pas d'erreur) | I4: À ajouter | J4: À exécuter
A5: CT-STAT-002 | B5: Stats nominales sur 30 jours | C5: Intégration | D5: Haute | E5: 3 entrées dans les 30 jours | F5: — | G5: GET /api/entries/stats | H5: totalEntries=3, dailyAverages avec moyenne par jour | I5: ✅ | J5: À exécuter
A6: CT-STAT-003 | B6: detailed-stats sans bornes → 400 | C6: Intégration | D6: Moyenne | E6: — | F6: — | G6: GET /api/entries/detailed-stats sans paramètres | H6: HTTP 400 | I6: ✅ | J6: À exécuter
A7: CT-STAT-004 | B7: detailed-stats — agrégats complets | C7: Intégration | D7: Haute | E7: Historique d'entrées | F7: startDate, endDate | G7: GET /api/entries/detailed-stats?startDate=...&endDate=... | H7: • totalEntries, averageIntensity • mostFrequentEmotion / Category • emotionDistribution[] et categoryDistribution[] • dailyAverages[] • weekdayDistribution[7], hourDistribution[24] • streakDays • contextTagsDistribution[] | I7: ✅ | J7: À exécuter
A8: CT-STAT-005 | B8: Streak de jours consécutifs | C8: Intégration | D8: Moyenne | E8: 3 entrées sur 3 jours consécutifs, puis trou de 5 jours, puis 2 entrées sur 2 jours | F8: — | G8: GET /api/entries/detailed-stats | H8: streakDays = 3 (max) | I8: ✅ tests/integration/entries.test.ts | J8: À exécuter
A9: CT-STAT-006 | B9: Distribution par jour de la semaine | C9: Intégration | D9: Moyenne | E9: — | F9: 5 entrées un lundi | G9: Créer 5 entrées un lundi puis GET stats | H9: weekdayDistribution[1].count = 5, percentage = 100 | I9: À ajouter | J9: À exécuter
A10: CT-STAT-007 | B10: Web : sélecteur de période | C10: E2E | D10: Haute | E10: Compte avec historique | F10: — | G10: /dashboard/statistiques → cliquer 'Cette semaine' puis 'Mois dernier' | H10: Refetch + KPI mis à jour | I10: Manuel | J10: À exécuter
A11: CT-STAT-008 | B11: Mobile : bascule 7j / 30j / 90j | C11: E2E Maestro | D11: Haute | E11: Compte avec historique | F11: — | G11: Onglet Stats → switch périodes | H11: Données cohérentes selon période | I11: ✅ 05-statistiques.yaml | J11: À exécuter
A12: CT-STAT-009 | B12: detailed-stats → résultat vide hors de la plage | C12: Intégration | D12: Moyenne | E12: User authentifié, entrées existantes hors plage | F12: startDate=2000-01-01, endDate=2000-01-02 | G12: GET /api/entries/detailed-stats?startDate=...&endDate=... | H12: HTTP 200 — totalEntries=0, streakDays=0 | I12: ✅ tests/integration/entries.test.ts | J12: À exécuter
A13: CT-STAT-010 | B13: GET /api/entries/stats → 401 sans token | C13: Intégration | D13: Bloquant | E13: Aucune session | F13: — | G13: GET /api/entries/stats sans Authorization | H13: HTTP 401 | I13: ✅ tests/integration/entries.test.ts | J13: À exécuter
A14: CT-STAT-011 | B14: GET /api/entries/detailed-stats → 401 sans token | C14: Intégration | D14: Bloquant | E14: Aucune session | F14: — | G14: GET /api/entries/detailed-stats sans Authorization | H14: HTTP 401 | I14: ✅ tests/integration/entries.test.ts | J14: À exécuter
A15: CT-STAT-012 | B15: Streak calculé sur jours consécutifs et non-consécutifs | C15: Intégration | D15: Moyenne | E15: Entrées aux jours J1, J2, J4 (gap J3) | F15: entries: 2024-06-01, 2024-06-02, 2024-06-04 | G15: GET /api/entries/detailed-stats sur la plage | H15: totalEntries=3, streakDays >= 2 | I15: ✅ tests/integration/entries.test.ts | J15: À exécuter

Sheet 9. CONS
A1: 9. Cas de test — CONS (Conseils / Articles)
A3: ID | B3: Titre | C3: Niveau | D3: Criticité | E3: Préconditions | F3: Données | G3: Étapes | H3: Résultat attendu | I3: Automatisé | J3: Statut | K3: Date exécution | L3: Testeur | M3: Commentaire | N3: ID anomalie
A4: CT-CONS-001 | B4: Liste publique des articles publiés | C4: Intégration | D4: Haute | E4: Articles publiés en DB | F4: — | G4: GET /api/articles?publishedOnly=true | H4: Seuls les articles avec isPublished=true | I4: ✅ | J4: À exécuter
A5: CT-CONS-002 | B5: Liste sans filtre (admin) | C5: Intégration | D5: Moyenne | E5: Articles publiés + brouillons | F5: — | G5: GET /api/articles | H5: Tous les articles (drafts inclus) | I5: ✅ | J5: À exécuter
A6: CT-CONS-003 | B6: Lookup par slug existant | C6: Intégration | D6: Haute | E6: Article slug='hello' | F6: — | G6: GET /api/articles/by-slug/hello | H6: HTTP 200 + article complet | I6: ✅ | J6: À exécuter
A7: CT-CONS-004 | B7: Lookup par slug inexistant | C7: Intégration | D7: Moyenne | E7: — | F7: — | G7: GET /api/articles/by-slug/nope | H7: HTTP 404 | I7: ✅ | J7: À exécuter
A8: CT-CONS-005 | B8: Recherche client par mot-clé | C8: Manuel | D8: Moyenne | E8: Articles divers | F8: Mot-clé | G8: /conseils → champ recherche → saisir un mot | H8: Liste filtrée (titre + content + excerpt) | I8: Manuel | J8: À exécuter
A9: CT-CONS-006 | B9: Filtre par catégorie | C9: Manuel + Mobile Maestro | D9: Moyenne | E9: Articles dans plusieurs catégories | F9: — | G9: Sélectionner une catégorie dans le filtre | H9: Seuls les articles de cette catégorie | I9: ✅ Mobile partiel | J9: À exécuter
A10: CT-CONS-007 | B10: Brouillon non visible côté public | C10: E2E | D10: Bloquant | E10: — | F10: Article isPublished=false | G10: • Créer article isPublished=false • GET /conseils (liste) • GET /conseils/<slug> direct | H10: • Liste : article absent • URL directe : redirige vers 'Article non trouvé' (vérification client) | I10: ✅ partiel | J10: À exécuter
A11: CT-CONS-008 | B11: Brouillon visible côté admin | C11: Manuel | D11: Haute | E11: Brouillon en base | F11: — | G11: Admin → /admin/articles | H11: Brouillons listés avec badge 'Brouillon' | I11: Manuel | J11: À exécuter
A12: CT-CONS-009 | B12: Article HTML rendu correctement | C12: Manuel | D12: Haute | E12: Article avec balises HTML | F12: — | G12: Lire un article avec <h1>, <ul>, <a>, <strong> | H12: Mise en forme préservée (web : dangerouslySetInnerHTML + Tailwind typography ; mobile : react-native-render-html avec styles) | I12: Manuel | J12: À exécuter
A13: CT-CONS-010 | B13: Web : navigation depuis article | C13: Manuel | D13: Basse | E13: — | F13: — | G13: Article → 'Retour aux conseils' | H13: Retour à la liste | I13: Manuel | J13: À exécuter
A14: CT-CONS-011 | B14: GET /api/articles/[id] → 404 si inexistant | C14: Intégration | D14: Moyenne | E14: ID inexistant | F14: id=00000000-0000-0000-0000-000000000000 | G14: GET /api/articles/[id] | H14: HTTP 404 | I14: ✅ tests/integration/articles-crud.test.ts | J14: À exécuter
A15: CT-CONS-012 | B15: GET /api/articles/[id] → retourne l'article | C15: Intégration | D15: Haute | E15: Article existant | F15: title='Hello', slug='hello' | G15: GET /api/articles/[id] | H15: HTTP 200 — body.title='Hello', body.slug='hello' | I15: ✅ tests/integration/articles-crud.test.ts | J15: À exécuter
... A17: CT-CONS-014 | B17: GET /api/articles/categories → avec données après seed | C17: Intégration | D17: Haute | E17: Catégorie seedée en base | F17: — | G17: GET /api/articles/categories | H17: HTTP 200 — body.length > 0 | I17: ✅ tests/integration/articles.test.ts | J17: À exécuter

Sheet 10. ADM
A1: 10. Cas de test — ADM (Administration)
A3: ID | B3: Titre | C3: Niveau | D3: Criticité | E3: Préconditions | F3: Données | G3: Étapes | H3: Résultat attendu | I3: Automatisé | J3: Statut | K3: Date exécution | L3: Testeur | M3: Commentaire | N3: ID anomalie
A4: CT-ADM-001 | B4: Accès /admin sans connexion | C4: E2E | D4: Bloquant | E4: Aucune session | F4: — | G4: GET /admin | H4: Redirect 307 vers /login | I4: ✅ Playwright | J4: À exécuter
A5: CT-ADM-002 | B5: Accès /admin en tant que user simple | C5: Intégration | D5: Bloquant (sécurité) | E5: Authentifié role=user | F5: — | G5: GET /admin | H5: Redirect vers /dashboard | I5: À ajouter | J5: À exécuter
A6: CT-ADM-003 | B6: Tableau de bord admin | C6: E2E | D6: Haute | E6: Admin connecté | F6: — | G6: Admin login → /admin | H6: KPI affichés : totalUsers, newUsersThisWeek, totalArticles, bannedUsers | I6: Manuel + admin.test.ts couvre l'API | J6: À exécuter
A7: CT-ADM-004 | B7: Liste utilisateurs | C7: Intégration | D7: Haute | E7: Admin authentifié | F7: — | G7: GET /api/admin/users (admin) | H7: Liste sans passwordHash | I7: ✅ | J7: À exécuter
A8: CT-ADM-005 | B8: Bannir un user | C8: Intégration | D8: Haute | E8: User cible existant | F8: {action:'toggleBan'} | G8: PATCH /api/admin/users/[id] body {action:'toggleBan'} | H8: HTTP 200 + isBanned=true | I8: ✅ | J8: À exécuter
A9: CT-ADM-006 | B9: Le user banni ne peut plus se connecter | C9: Intégration | D9: Bloquant | E9: Suite à CT-ADM-005 | F9: — | G9: POST /api/auth/login avec ce user | H9: HTTP 403 | I9: ✅ (couvert par CT-AUTH-007) | J9: À exécuter
A10: CT-ADM-007 | B10: Refus de l'auto-modification | C10: Intégration | D10: Haute (sécurité) | E10: Admin connecté | F10: — | G10: PATCH /api/admin/users/[idAdminConnecté] | H10: HTTP 400 + body.error « propre compte » | I10: ✅ | J10: À exécuter
A11: CT-ADM-008 | B11: Refus de bannir un autre admin | C11: Intégration | D11: Haute | E11: 2 admins en base | F11: action=toggleBan | G11: PATCH avec target=autre admin, action=toggleBan | H11: HTTP 400 | I11: ✅ | J11: À exécuter
A12: CT-ADM-009 | B12: Promotion d'un user en admin | C12: Intégration | D12: Haute | E12: User existant | F12: action=toggleRole | G12: PATCH avec action=toggleRole | H12: HTTP 200 + role='admin' | I12: ✅ tests/integration/admin.test.ts | J12: À exécuter
A13: CT-ADM-010 | B13: Suppression d'un user | C13: Intégration | D13: Haute | E13: User cible | F13: — | G13: DELETE /api/admin/users/[id] (target = user) | H13: HTTP 200 + user supprimé + cascade sur entries | I13: ✅ tests/integration/admin.test.ts | J13: À exécuter
A14: CT-ADM-011 | B14: Refus de suppression d'un admin | C14: Intégration | D14: Haute | E14: Autre admin existant | F14: — | G14: DELETE sur autre admin | H14: HTTP 400 | I14: ✅ | J14: À exécuter
A15: CT-ADM-012 | B15: CRUD article admin | C15: Intégration | D15: Haute | E15: Admin authentifié | F15: Article complet | G15: • POST /api/articles (admin) • PUT • DELETE | H15: Cycle complet OK + slug unique enforced (409 sinon) | I15: Partiel | J15: À exécuter
... A38: CT-ADM-035 | B38: POST article → 409 conflit de slug | C38: Intégration | D38: Haute | E38: Session admin, article "existing" déjà en base | F38: { slug: "existing" } | G38: POST /api/articles | H38: HTTP 409 | I38: ✅ tests/integration/articles.test.ts | J38: À exécuter

Sheet 11. MOB
A1: 11. Cas de test — MOB (Mobile spécifique)
A3: ID | B3: Titre | C3: Niveau | D3: Criticité | E3: Préconditions | F3: Données | G3: Étapes | H3: Résultat attendu | I3: Automatisé | J3: Statut | K3: Date exécution | L3: Testeur | M3: Commentaire | N3: ID anomalie
A4: CT-MOB-001 | B4: Persistance de session après redémarrage | C4: Manuel | D4: Bloquant | E4: App installée | F4: — | G4: Login → tuer l'app → relancer | H4: Reste connecté (token relu depuis SecureStore, /api/auth/me répond) | I4: Partiel via Jest (mock SecureStore) | J4: À exécuter
A5: CT-MOB-002 | B5: Token effacé après logout | C5: Unitaire | D5: Bloquant (sécurité) | E5: App authentifiée | F5: — | G5: Login → Logout → relancer | H5: Affiche écran login (token absent) | I5: ✅ Jest AuthContext.test.tsx | J5: À exécuter
A6: CT-MOB-003 | B6: Bearer token dans toutes les requêtes authentifiées | C6: Unitaire | D6: Bloquant | E6: App authentifiée | F6: — | G6: Inspecter une requête authentifiée (DevTools) | H6: Header Authorization: Bearer <jwt> présent | I6: ✅ Jest api.test.ts | J6: À exécuter
A7: CT-MOB-004 | B7: Pas de Bearer pour les endpoints publics | C7: Unitaire | D7: Moyenne | E7: — | F7: — | G7: GET articles (publié) | H7: Pas de header Authorization (économie token, propreté) | I7: ✅ | J7: À exécuter
A8: CT-MOB-005 | B8: Erreur HTTP propage le body.error | C8: Unitaire | D8: Moyenne | E8: — | F8: — | G8: Provoquer une 401 | H8: UI affiche le message du serveur | I8: ✅ Jest | J8: À exécuter
A9: CT-MOB-006 | B9: Pull-to-refresh sur le journal | C9: Manuel | D9: Moyenne | E9: App authentifiée | F9: — | G9: Onglet Journal → tirer vers le bas | H9: Spinner + refetch via TanStack Query | I9: Manuel | J9: À exécuter
A10: CT-MOB-007 | B10: Cache TanStack Query staleTime | C10: Manuel | D10: Basse | E10: App authentifiée | F10: — | G10: Naviguer entre 2 onglets puis revenir | H10: Pas de re-fetch si < 60s (staleTime configuré) | I10: Manuel | J10: À exécuter
A11: CT-MOB-008 | B11: Invalidation après création d'entrée | C11: Manuel | D11: Haute | E11: App authentifiée | F11: — | G11: Onglet Journal → ajouter une entrée → revenir | H11: Liste mise à jour (queryClient.invalidateQueries) | I11: Manuel | J11: À exécuter
A12: CT-MOB-009 | B12: Picker d'émotion en 2 étapes | C12: Manuel | D12: Haute | E12: App authentifiée | F12: — | G12: Nouvelle entrée → choisir catégorie → choisir émotion | H12: UI cohérente, sélection mémorisée | I12: Manuel | J12: À exécuter
A13: CT-MOB-010 | B13: Slider d'intensité 0-5 | C13: Unitaire | D13: Moyenne | E13: — | F13: — | G13: Glisser le slider | H13: Valeur snap aux pas entiers, label change ('Faible' → 'Très élevée') | I13: ✅ Jest IntensityPicker | J13: À exécuter
A14: CT-MOB-011 | B14: Calendrier journal — points colorés | C14: Manuel | D14: Moyenne | E14: Entrées en base | F14: — | G14: Onglet Journal → vue calendrier | H14: Dates avec entrée marquées d'un point primary | I14: Manuel | J14: À exécuter
A15: CT-MOB-012 | B15: Article HTML — heading / liste / lien | C15: Manuel | D15: Haute | E15: Article avec HTML riche | F15: — | G15: Ouvrir un article complexe | H15: h1/h2/h3, ul/ol, lien cliquable, italique, gras OK | I15: Manuel | J15: À exécuter
... A27: CT-MOB-024 | B27: storeToken — rejet si token vide ou undefined | C27: Unitaire | D27: Haute | E27: — | F27: token='' ou token=undefined | G27: storeToken('') ou storeToken(undefined) | H27: Exception avec message "Invalid token" | I27: ✅ mobile/__tests__/lib/auth.test.ts | J27: À exécuter

Sheet 12. SEC
A1: 12. Cas de test — SEC (Sécurité)
A3: ID | B3: Titre | C3: Niveau | D3: Criticité | E3: Préconditions | F3: Données | G3: Étapes | H3: Résultat attendu | I3: Automatisé | J3: Statut | K3: Date exécution | L3: Testeur | M3: Commentaire | N3: ID anomalie
A4: CT-SEC-001 | B4: Notes utilisateur chiffrées au repos | C4: Sécurité | D4: Bloquant (RGPD) | E4: Entrées en base | F4: — | G4: • Inspecter entries.note_encrypted directement • Vérifier l'absence de la note en clair | H4: Format AES-256-GCM iv:tag:cipher | I4: ✅ | J4: À exécuter
A5: CT-SEC-002 | B5: Mots de passe non stockés en clair | C5: Sécurité | D5: Bloquant | E5: Comptes en base | F5: — | G5: SELECT password_hash FROM users | H5: Format salt:hash hex (scrypt), pas le mot de passe | I5: ✅ | J5: À exécuter
A6: CT-SEC-003 | B6: Brute-force timing attack | C6: Sécurité | D6: Haute | E6: — | F6: — | G6: Mesurer le temps de réponse pour : email valide / mauvais mdp vs email inconnu | H6: Diff < 50ms (timingSafeEqual + lookup similaires) | I6: Manuel | J6: À exécuter
A7: CT-SEC-004 | B7: JWT signature altérée | C7: Sécurité | D7: Bloquant | E7: JWT valide | F7: — | G7: Modifier la signature d'un token, l'envoyer | H7: session = null, requête refusée | I7: ✅ CT-AUTH-010 | J7: À exécuter
A8: CT-SEC-005 | B8: JWT payload modifié (élévation de privilège) | C8: Sécurité | D8: Bloquant | E8: JWT user | F8: — | G8: Tenter de modifier le payload pour passer role=admin sans re-signer | H8: Vérification HMAC échoue → null | I8: ✅ par jose | J8: À exécuter
A9: CT-SEC-006 | B9: IDOR (lecture entrée d'un autre user) | C9: Sécurité | D9: Bloquant | E9: Entrée userA, token userB | F9: — | G9: GET /api/entries/<uuid-de-userA> avec token userB | H9: HTTP 404 | I9: ✅ CT-JRN-010 | J9: À exécuter
A10: CT-SEC-007 | B10: XSS dans la note (saisie utilisateur) | C10: Sécurité | D10: Haute | E10: — | F10: note='<script>alert(1)</script>' | G10: Créer entrée avec script tag | H10: • Web : note affichée en texte brut (pas d'exécution) • Mobile : idem (Text component) | I10: Manuel | J10: À exécuter
A11: CT-SEC-008 | B11: XSS dans le contenu d'un article (admin) | C11: Sécurité | D11: Haute | E11: Admin connecté | F11: Contenu HTML | G11: Admin entre du HTML rendu via dangerouslySetInnerHTML | H11: À risque par design — la confiance est placée sur le compte admin. À documenter explicitement. (TipTap utilisé : sanitize amont, revue admin) | I11: Non | J11: À exécuter
A12: CT-SEC-009 | B12: SQL injection | C12: Sécurité | D12: Bloquant | E12: — | F12: email="'; DROP TABLE users;--" | G12: Soumettre email avec injection SQL | H12: Drizzle utilise des requêtes paramétrées, aucune exécution | I12: Manuel + couvert par les tests intégration | J12: À exécuter
A13: CT-SEC-010 | B13: CSRF (Cross-Site Request Forgery) | C13: Sécurité | D13: Haute | E13: — | F13: — | G13: Cookie sameSite=lax configuré dans createSession | H13: Les requêtes cross-site n'envoient pas le cookie automatiquement | I13: Couvert par lecture du code | J13: À exécuter
A14: CT-SEC-011 | B14: Headers de sécurité | C14: Sécurité | D14: Moyenne | E14: — | F14: — | G14: Inspecter les headers de réponse | H14: À auditer : CSP, X-Frame-Options, X-Content-Type-Options, Strict-Transport-Security (à compléter en production) | I14: Manuel — non implémenté actuellement | J14: À exécuter
A15: CT-SEC-012 | B15: Brute-force login (rate limiting) | C15: Sécurité | D15: Haute | E15: — | F15: — | G15: Pas de rate limiter actuellement → backlog | H15: À implémenter (Upstash Ratelimit, middleware) | I15: Non — anomalie connue | J15: À exécuter
... A21: CT-SEC-018 | B21: Chiffrement — erreur si ENCRYPTION_KEY absente | C21: Unitaire | D21: Bloquant | E21: ENCRYPTION_KEY supprimée des variables d'env | F21: — | G21: encryptNote("test") | H21: Exception "ENCRYPTION_KEY environment variable is not set" | I21: ✅ tests/unit/encryption.test.ts | J21: À exécuter

Sheet 14. EMO
A1: 14. Cas de test — EMO (Émotions)
A3: ID | B3: Titre | C3: Niveau | D3: Criticité | E3: Préconditions | F3: Données | G3: Étapes | H3: Résultat attendu | I3: Automatisé | J3: Statut | K3: Date exécution | L3: Testeur | M3: Commentaire | N3: ID anomalie
A4: CT-EMO-001 | B4: GET /api/emotions → liste vide | C4: Intégration | D4: Moyenne | E4: Base vide | F4: — | G4: GET /api/emotions | H4: HTTP 200 — body=[] | I4: ✅ tests/integration/emotions.test.ts | J4: À exécuter
A5: CT-EMO-002 | B5: GET /api/emotions → retourne émotions après seed | C5: Intégration | D5: Haute | E5: Émotion "Heureux" seedée | F5: — | G5: GET /api/emotions | H5: HTTP 200 — body.length > 0 | I5: ✅ tests/integration/emotions.test.ts | J5: À exécuter
A6: CT-EMO-003 | B6: GET /api/emotions/[id] → 404 si inexistant | C6: Intégration | D6: Moyenne | E6: Aucune émotion id=9999 | F6: id=9999 | G6: GET /api/emotions/9999 | H6: HTTP 404 | I6: ✅ tests/integration/emotions-crud.test.ts | J6: À exécuter
A7: CT-EMO-004 | B7: GET /api/emotions/[id] → retourne l'émotion | C7: Intégration | D7: Haute | E7: Émotion "Heureux" seedée | F7: — | G7: GET /api/emotions/[id] | H7: HTTP 200 — body.label="Heureux" | I7: ✅ tests/integration/emotions-crud.test.ts | J7: À exécuter
A8: CT-EMO-005 | B8: PUT /api/emotions/[id] → 403 sans session admin | C8: Intégration | D8: Bloquant (sécurité) | E8: Aucune session admin | F8: { label: "X", categoryId: 1 } | G8: PUT /api/emotions/1 sans session | H8: HTTP 403 | I8: ✅ tests/integration/emotions-crud.test.ts | J8: À exécuter
A9: CT-EMO-006 | B9: PUT /api/emotions/[id] → 400 validation | C9: Intégration | D9: Haute | E9: Session admin | F9: { label: "", categoryId: "not-a-number" } | G9: PUT /api/emotions/1 | H9: HTTP 400 — body.fieldErrors défini | I9: ✅ tests/integration/emotions-crud.test.ts | J9: À exécuter
A10: CT-EMO-007 | B10: PUT /api/emotions/[id] → mise à jour nominale | C10: Intégration | D10: Haute | E10: Session admin, émotion seedée | F10: { label: "Très heureux", categoryId: catId } | G10: PUT /api/emotions/[id] | H10: HTTP 200 — body.success === true | I10: ✅ tests/integration/emotions-crud.test.ts | J10: À exécuter
A11: CT-EMO-008 | B11: DELETE /api/emotions/[id] → 403 sans session admin | C11: Intégration | D11: Bloquant (sécurité) | E11: Aucune session admin | F11: — | G11: DELETE /api/emotions/1 sans session | H11: HTTP 403 | I11: ✅ tests/integration/emotions-crud.test.ts | J11: À exécuter
A12: CT-EMO-009 | B12: DELETE /api/emotions/[id] → suppression nominale | C12: Intégration | D12: Haute | E12: Session admin, émotion seedée | F12: — | G12: DELETE /api/emotions/[id] | H12: HTTP 200 — body.success === true | I12: ✅ tests/integration/emotions-crud.test.ts | J12: À exécuter
A13: CT-EMO-010 | B13: GET /api/emotions/categories → liste vide | C13: Intégration | D13: Moyenne | E13: Aucune catégorie | F13: — | G13: GET /api/emotions/categories | H13: HTTP 200 — body est un tableau | I13: ✅ tests/integration/emotions.test.ts | J13: À exécuter
A14: CT-EMO-011 | B14: GET /api/emotions/categories → avec données après seed | C14: Intégration | D14: Haute | E14: Catégorie seedée | F14: — | G14: GET /api/emotions/categories | H14: HTTP 200 — body.length > 0 | I14: ✅ tests/integration/emotions.test.ts | J14: À exécuter
A15: CT-EMO-012 | B15: GET /api/emotions/categories/[id] → 404 si inexistant | C15: Intégration | D15: Moyenne | E15: Aucune catégorie id=9999 | F15: id=9999 | G15: GET /api/emotions/categories/9999 | H15: HTTP 404 | I15: ✅ tests/integration/emotions-crud.test.ts | J15: À exécuter
... A24: CT-EMO-021 | B24: POST /api/emotions/categories → création nominale | C24: Intégration | D24: Haute | E24: Session admin | F24: { label: "Peur", colorHex: "#800080", iconName: "fear" } | G24: POST /api/emotions/categories | H24: HTTP 200 — body.success === true | I24: ✅ tests/integration/emotions.test.ts | J24: À exécuter

Sheet 13. Régression
A1: 13. Plan de régression
A3: À exécuter avant chaque release, sur l'environnement de recette.
A5: 13.1 Régression critique (~25 min)
A6: ID | B6: Description | C6: Module
A7: CT-AUTH-001 | B7: Inscription nominale | C7: AUTH
A8: CT-AUTH-004 | B8: Login nominal | C8: AUTH
A9: CT-AUTH-007 | B9: Login refusé compte banni | C9: AUTH
A10: CT-JRN-002 | B10: Création entrée avec note | C10: JRN
A11: CT-JRN-003 | B11: Lecture déchiffrée | C11: JRN
A12: CT-JRN-005 | B12: Note chiffrée en DB | C12: JRN
A13: CT-JRN-009 | B13: Ownership lecture | C13: JRN
A14: CT-JRN-010 | B14: Ownership lecture par ID | C14: JRN
A15: CT-STAT-002 | B15: Stats 30j | C15: STAT
A16: CT-CONS-007 | B16: Brouillon non visible | C16: CONS
A17: CT-ADM-001 | B17: Accès admin sans connexion | C17: ADM
... A23: CT-SEC-006 | B23: IDOR refusé | C23: SEC
A25: 13.2 Régression complète
A26: L'intégralité des 90+ cas — exécutée 1× par mois ou avant une release majeure.

Sheet Annexe A
A1: Annexe A — Modèle de fiche d'anomalie
A3: Champ | B3: Valeur
A4: ID anomalie | B4: ANO-2026-XXX
A5: Date | B5: 2026-MM-JJ
A6: Détecté par | B6: <nom>
A7: Environnement | B7: Local / Recette / Prod
A8: Cas de test | B8: CT-XXX-YYY
A9: Sévérité | B9: Bloquante / Majeure / Mineure / Cosmétique
A10: Statut | B10: Ouvert / En cours / Corrigé / Vérifié / Fermé
A11: Module | B11: AUTH / JRN / STAT / CONS / ADM / MOB / SEC
A12: Description | B12: <description courte>
A13: Étapes pour reproduire | B13: 1. ... 2. ...
A14: Résultat observé | B14: ...
... A20: Test de NR | B20: <CT à ajouter / modifier>

Sheet Annexe B
A1: Annexe B — Classification des anomalies
A3: Sévérité | B3: Critères | C3: Exemple | D3: Délai correctif
A4: Bloquante | B4: Empêche l'utilisation OU compromet la sécurité OU perte de données | C4: Login impossible, IDOR, leak de données | D4: Hot-fix < 24 h
A5: Majeure | B5: Fonctionnalité importante dégradée | C5: Stats fausses, ban contournable, crash récurrent | D5: Avant release
A6: Mineure | B6: Gêne mineure, contournement existe | C6: Filtre articles bug, message erreur peu clair | D6: Version + 1
A7: Cosmétique | B7: Visuel, libellé, animation | C7: Typo, couleur off, animation saccadée | D7: Backlog
A10: Décision de mise en production
A11: Bloquantes ouvertes | B11: Majeures ouvertes | C11: Décision
A12: 0 | B12: 0 | C12: ✅ Go production
A13: 0 | B13: ≤ 2 documentées | C13: ⚠ Go avec réserves (PV signé)
A14: 0 | B14: > 2 | C14: ❌ No-go, correctifs requis
A15: ≥ 1 | B15: * | C15: ❌ No-go absolu
